<?xml version="1.0"?>
<robot xmlns:xacro="http://www.ros.org/wiki/xacro" name="jakaUr">
<xacro:property name="pi" value="3.14159265358"/>

 <material name="blue">
    <color rgba="0 0 0.8 1"/>
  </material>

  <material name="black">
    <color rgba="0 0 0 1"/>
  </material>

  <material name="white">
    <color rgba="1 1 1 1"/>
  </material>

  <link name="base_link">
    <visual>
      <origin rpy="0 ${pi / 2} 0" xyz="0 0 0"/>
      <geometry>
        <mesh filename="file:///home/shantengfei/Documents/urStl/p1.dae"/>
      </geometry>
    </visual>

    <collision>
      <geometry>
         <mesh filename="file:///home/shantengfei/Documents/urStl/p1.dae"/>
     </geometry>
      <origin rpy="0 ${pi / 2} 0" xyz="0 0 0"/>
    </collision>
  </link>

  <link name="link_1">
    <visual>
      <geometry>
         <mesh filename="file:///home/shantengfei/Documents/urStl/p2.dae"/>
      </geometry>
      <origin rpy=" ${pi/2.0}  0  ${-pi/2.0}" xyz="0 0 0"/>
    </visual>

    <collision>
      <geometry>
         <mesh filename="file:///home/shantengfei/Documents/urStl/p2.dae"/>
      </geometry>
      <origin rpy="${pi/2.0} 0 ${-pi/2.0}" xyz="0 0 0"/>
  </collision>

  </link>



  <joint name="joint_1" type="revolute">
   <axis xyz="0 0 1"/>
    <limit effort="1000" lower="-1.58" upper="1.58" velocity="0.5"/>
    <origin rpy="0 0 0" xyz="0 0 0.094"/>
    <parent link="base_link"/>
    <child link="link_1"/>
  </joint>

  <link name="link_2">
    <visual>
      <geometry>
         <mesh filename="file:///home/shantengfei/Documents/urStl/p3.dae"/>
      </geometry>
      <origin rpy="${pi/2.0} ${-pi/2.0} ${5.0*pi/6.0}" xyz="0 0 0"/> 
   </visual>

    <collision>
   <geometry>
         <mesh filename="file:///home/shantengfei/Documents/urStl/p3.dae"/>
      </geometry>
      <origin rpy="${pi/2.0} ${-pi/2.0} ${5.0*pi/6.0} " xyz="0 0 0"/> 
  </collision> 

  </link>



  <joint name="joint_2" type="revolute">
   <axis xyz="0 0 1"/>
    <limit effort="1000" lower="-1.58" upper="3.58" velocity="0.5"/>
    <origin rpy="${pi/2.0} 0 0" xyz="0 0 0"/>
    <parent link="link_1"/>
    <child link="link_2"/>
  </joint>


  <link name="link_3">
    <visual>
      <geometry>
         <mesh filename="file:///home/shantengfei/Documents/urStl/p42.dae"/>
      </geometry>
      <origin rpy="0 0 ${-pi/2.0}" xyz="0 0 0.0135"/> 
   </visual>
     <collision>
    <geometry>
         <mesh filename="file:///home/shantengfei/Documents/urStl/p42.dae"/>
      </geometry>
      <origin rpy="0 0 ${-pi/2.0}" xyz="0 0 0.0135"/> 
   </collision>

  </link>


  <joint name="joint_3" type="revolute">
   <axis xyz="0 0 1"/>
    <limit effort="1000" lower="-1.58" upper="3.58" velocity="0.5"/>
    <origin rpy="0 0 0" xyz="0.353 0 0"/>
    <parent link="link_2"/>
    <child link="link_3"/>
  </joint>

  <link name="link_4">
    <visual>
      <geometry>
         <mesh filename="file:///home/shantengfei/Documents/urStl/p54.dae"/>
      </geometry>
      <origin rpy="${-pi/2.0} 0 ${pi/2.0}" xyz="0 0 0"/> 
   </visual>
    <collision>
  <geometry>
         <mesh filename="file:///home/shantengfei/Documents/urStl/p54.dae"/>
      </geometry>
      <origin rpy="${-pi/2.0} 0 ${pi/2.0}" xyz="0 0 0"/> 
    </collision>
  
  </link>


  <joint name="joint_4" type="revolute">
   <axis xyz="0 0 1"/>
    <limit effort="1000" lower="-1.58" upper="3.58" velocity="0.5"/>
    <origin rpy="0 0 0" xyz="0.31 0 0.109"/>
    <parent link="link_3"/>
    <child link="link_4"/>
  </joint>

  <link name="link_5">
    <visual>
      <geometry>
         <mesh filename="file:///home/shantengfei/Documents/urStl/p6.dae"/>
      </geometry>
      <origin rpy="${pi} 0 ${-pi/2.0}" xyz="0 0 0"/> 
   </visual>

    <collision>
     <geometry>
         <mesh filename="file:///home/shantengfei/Documents/urStl/p6.dae"/>
      </geometry>
      <origin rpy="${pi} 0 ${-pi/2.0}" xyz="0 0 0"/> 
  </collision> 

  </link>


  <joint name="joint_5" type="revolute">
   <axis xyz="0 0 1"/>
    <limit effort="1000" lower="-1.58" upper="3.58" velocity="0.5"/>
    <origin rpy="${pi/2.0} 0 0" xyz="0 -0.0955 0"/>
    <parent link="link_4"/>
    <child link="link_5"/>
  </joint>


  <link name="link_6">
    <visual>
      <geometry>
         <mesh filename="file:///home/shantengfei/Documents/urStl/p7.dae"/>
      </geometry>
      <origin rpy="${-pi} 0 0" xyz="0 0 0.03"/> 
   </visual>

       <collision>
      <geometry>
         <mesh filename="file:///home/shantengfei/Documents/urStl/p7.dae"/>
      </geometry>
      <origin rpy="${-pi} 0 0" xyz="0 0 0.03"/> 
       </collision> 

  </link>


  <joint name="joint_6" type="revolute">
   <axis xyz="0 0 1"/>
    <limit effort="1000" lower="-1.58" upper="3.58" velocity="0.5"/>
    <origin rpy="${pi/2.0} 0 0" xyz="0 0.085 0"/>
    <parent link="link_5"/>
    <child link="link_6"/>
  </joint>

</robot>
